<?xml version="1.0" ?>
<!-- =================================================================================== -->
<!-- |    This document was autogenerated by xacro from altair_compose.urdf.xacro      | -->
<!-- |    EDITING THIS FILE BY HAND IS NOT RECOMMENDED                                 | -->
<!-- =================================================================================== -->
<robot name="altair">
  <!-- README! -->
  <!-- This is xacro file is for configure ros2_control, managing available hardware: sensors,
  joints, etc.
  This configuration will be used by ros2_control hardware abstraction, there are 20 joints, 1 IMU,
  and 1 Microcontroller hardware.
  There are 3 modes available: 
  1. real_mode: true = ros2_control will call MicrocontrollerHardware and DynamixelHardware. This is
  used for real robot.
  2. mock_mode: true = ros2_control will call GenericSystem. This is used for simulation with mock
  mode. or no pyshics sim, just a mock.
  3. sim_mode: true  = ros2_control will call GazeboSimSystem. This is used for simulation with gazebo
  sim.
  !!! Caution !!! Modes can only be set true for single mode. It cant be true for multiple mode. Set
  it with caution.
  Modes can be set in launch file. -->
  <link name="odom"/>
  <joint name="base_fixed" type="fixed">
    <parent link="odom"/>
    <child link="body_link"/>
    <origin rpy="0 0 0" xyz="0 0 0.0"/>
  </joint>
  <!--   body link-->
  <link name="body_link">
    <visual>
      <origin rpy="0.00000 0.00000 0.00000" xyz="0.00000 0.00000 0.00000"/>
      <geometry>
        <mesh filename="meshes/body.stl" scale="1.00000 1.00000 1.00000"/>
      </geometry>
      <material name="254,254,255.002">
        <color rgba="0.99216 0.99216 1.00000 1.00000"/>
      </material>
    </visual>
    <collision>
      <origin rpy="0.00000 0.00000 0.00000" xyz="0.00000 0.00000 0.00000"/>
      <geometry>
        <mesh filename="meshes/body.stl" scale="1.00000 1.00000 1.00000"/>
      </geometry>
      <material name="254,254,255.002">
        <color rgba="0.99216 0.99216 1.00000 1.00000"/>
      </material>
    </collision>
    <inertial>
      <inertia ixx="0.00639" ixy="-0.00001" ixz="-0.00019" iyy="0.00522" iyz="-0.00003" izz="0.00297"/>
      <origin rpy="0.00000 0.00000 0.00000" xyz="0.00091 -0.00121 0.09355"/>
      <mass value="1.34928"/>
    </inertial>
  </link>
  <!-- imu joint -->
  <joint name="imu_fixed" type="fixed">
    <parent link="body_link"/>
    <child link="imu_link"/>
    <origin rpy="0 0 0" xyz="0 0 0"/>
  </joint>
  <link name="imu_link"/>
  <!-- left hip yaw joint -->
  <joint name="l_hip_yaw" type="revolute">
    <parent link="body_link"/>
    <child link="l_hip_yaw_link"/>
    <origin rpy="0.00000 0.00000 0.00000" xyz="0.02448 0.04340 0.03887"/>
    <axis xyz="0.00000 0.00000 -1.00000"/>
    <limit effort="1000" lower="-2.827433388230814" upper="2.827433388230814" velocity="100"/>
    <dynamics damping="0.1" friction="0.0"/>
  </joint>
  <!-- left hip yaw link -->
  <link name="l_hip_yaw_link">
    <visual>
      <origin rpy="0.00000 0.00000 0.00000" xyz="-0.02809 -0.00006 -0.06018"/>
      <geometry>
        <mesh filename="meshes/l_hip_yaw.stl" scale="1.00000 1.00000 1.00000"/>
      </geometry>
      <material name="254,254,255.002">
        <color rgba="0.99216 0.99216 1.00000 1.00000"/>
      </material>
    </visual>
    <collision>
      <origin rpy="0.00000 0.00000 0.00000" xyz="-0.02809 -0.00006 -0.06018"/>
      <geometry>
        <mesh filename="meshes/l_hip_yaw.stl" scale="1.00000 1.00000 1.00000"/>
      </geometry>
      <material name="254,254,255.002">
        <color rgba="0.99216 0.99216 1.00000 1.00000"/>
      </material>
    </collision>
    <inertial>
      <inertia ixx="3.006331e-06" ixy="0" ixz="0" iyy="5.715429e-06" iyz="0" izz="4.2714855e-06"/>
      <origin rpy="0.00000 0.00000 0.00000" xyz="0.00587 -0.00015 -0.05907"/>
      <mass value="0.01181"/>
    </inertial>
  </link>
  <!-- left hip roll joint -->
  <joint name="l_hip_roll" type="revolute">
    <parent link="l_hip_yaw_link"/>
    <child link="l_hip_roll_link"/>
    <origin rpy="0.00000 0.00000 0.00000" xyz="-0.06106 -0.00006 -0.07670"/>
    <axis xyz="-1.00000 0.00000 0.00000"/>
    <limit effort="1000" lower="-2.827433388230814" upper="2.827433388230814" velocity="100"/>
    <dynamics damping="0.1" friction="0.0"/>
  </joint>
  <!-- left hip roll link -->
  <link name="l_hip_roll_link">
    <visual>
      <origin rpy="0.00000 0.00000 0.00000" xyz="0.03297 -0.00000 0.01652"/>
      <geometry>
        <mesh filename="meshes/l_hip_roll.stl" scale="1.00000 1.00000 1.00000"/>
      </geometry>
      <material name="254,254,255.002">
        <color rgba="0.99216 0.99216 1.00000 1.00000"/>
      </material>
    </visual>
    <collision>
      <origin rpy="0.00000 0.00000 0.00000" xyz="0.03297 -0.00000 0.01652"/>
      <geometry>
        <mesh filename="meshes/l_hip_roll.stl" scale="1.00000 1.00000 1.00000"/>
      </geometry>
      <material name="254,254,255.002">
        <color rgba="0.99216 0.99216 1.00000 1.00000"/>
      </material>
    </collision>
    <inertial>
      <inertia ixx="0.00006" ixy="0.00000" ixz="-0.00001" iyy="0.00016" iyz="0.00000" izz="0.00014"/>
      <origin rpy="0.00000 0.00000 0.00000" xyz="0.03366 -0.00021 -0.01480"/>
      <mass value="0.17886"/>
    </inertial>
  </link>
  <!-- left hip pitch joint -->
  <joint name="l_hip_pitch" type="revolute">
    <parent link="l_hip_roll_link"/>
    <child link="l_hip_pitch_link"/>
    <origin rpy="0.00000 0.00000 0.00000" xyz="0.05652 -0.02942 0.00064"/>
    <axis xyz="0.00000 1.00000 0.00000"/>
    <limit effort="1000" lower="-2.827433388230814" upper="2.827433388230814" velocity="100"/>
    <dynamics damping="0.1" friction="0.0"/>
  </joint>
  <!-- left hip pitch link -->
  <link name="l_hip_pitch_link">
    <visual>
      <origin rpy="0.00000 0.00000 0.00000" xyz="0.00072 0.02934 -0.09142"/>
      <geometry>
        <mesh filename="meshes/l_hip_pitch.stl" scale="1.00000 1.00000 1.00000"/>
      </geometry>
      <material name="254,254,255.002">
        <color rgba="0.99216 0.99216 1.00000 1.00000"/>
      </material>
    </visual>
    <collision>
      <origin rpy="0.00000 0.00000 0.00000" xyz="0.00072 0.02934 -0.09142"/>
      <geometry>
        <mesh filename="meshes/l_hip_pitch.stl" scale="1.00000 1.00000 1.00000"/>
      </geometry>
      <material name="254,254,255.002">
        <color rgba="0.99216 0.99216 1.00000 1.00000"/>
      </material>
    </collision>
    <inertial>
      <inertia ixx="0.00016" ixy="-0.00000" ixz="0.00000" iyy="0.00014" iyz="-0.00001" izz="0.00004"/>
      <origin rpy="0.00000 0.00000 0.00000" xyz="0.00062 0.02954 -0.07102"/>
      <mass value="0.11543"/>
    </inertial>
  </link>
  <!-- left knee joint -->
  <joint name="l_knee" type="revolute">
    <parent link="l_hip_pitch_link"/>
    <child link="l_knee_link"/>
    <origin rpy="0.00000 0.00000 0.00000" xyz="0.00089 -0.00563 -0.11729"/>
    <axis xyz="0.00000 1.00000 0.00000"/>
    <limit effort="1000" lower="-2.827433388230814" upper="2.827433388230814" velocity="100"/>
    <dynamics damping="0.1" friction="0.0"/>
  </joint>
  <!-- left knee link -->
  <link name="l_knee_link">
    <visual>
      <origin rpy="0.00000 0.00000 0.00000" xyz="0.00120 0.03658 -0.05859"/>
      <geometry>
        <mesh filename="meshes/l_knee.stl" scale="1.00000 1.00000 1.00000"/>
      </geometry>
      <material name="254,254,255.002">
        <color rgba="0.99216 0.99216 1.00000 1.00000"/>
      </material>
    </visual>
    <collision>
      <origin rpy="0.00000 0.00000 0.00000" xyz="0.00120 0.03658 -0.05859"/>
      <geometry>
        <mesh filename="meshes/l_knee.stl" scale="1.00000 1.00000 1.00000"/>
      </geometry>
      <material name="254,254,255.002">
        <color rgba="0.99216 0.99216 1.00000 1.00000"/>
      </material>
    </collision>
    <inertial>
      <inertia ixx="0.00006" ixy="-0.00000" ixz="0.00000" iyy="0.00004" iyz="-0.00000" izz="0.00002"/>
      <origin rpy="0.00000 0.00000 0.00000" xyz="0.00138 0.03706 -0.05861"/>
      <mass value="0.04015"/>
    </inertial>
  </link>
  <!-- left ankle pitch joint -->
  <joint name="l_ank_pitch" type="revolute">
    <parent link="l_knee_link"/>
    <child link="l_ank_pitch_link"/>
    <origin rpy="0.00000 0.00000 0.00000" xyz="0.00062 0.04741 -0.11684"/>
    <axis xyz="0.00000 -1.00000 0.00000"/>
    <limit effort="1000" lower="-2.827433388230814" upper="2.827433388230814" velocity="100"/>
    <dynamics damping="0.1" friction="0.0"/>
  </joint>
  <!-- left ankle pitch link -->
  <link name="l_ank_pitch_link">
    <visual>
      <origin rpy="0.00000 0.00000 0.00000" xyz="-0.00066 -0.01275 -0.01491"/>
      <geometry>
        <mesh filename="meshes/l_ank_pitch.stl" scale="1.00000 1.00000 1.00000"/>
      </geometry>
      <material name="254,254,255.002">
        <color rgba="0.99216 0.99216 1.00000 1.00000"/>
      </material>
    </visual>
    <collision>
      <origin rpy="0.00000 0.00000 0.00000" xyz="-0.00066 -0.01275 -0.01491"/>
      <geometry>
        <mesh filename="meshes/l_ank_pitch.stl" scale="1.00000 1.00000 1.00000"/>
      </geometry>
      <material name="254,254,255.002">
        <color rgba="0.99216 0.99216 1.00000 1.00000"/>
      </material>
    </collision>
    <inertial>
      <inertia ixx="0.00006" ixy="0.00000" ixz="0.00000" iyy="0.00016" iyz="0.00000" izz="0.00014"/>
      <origin rpy="0.00000 0.00000 0.00000" xyz="-0.02272 -0.01248 -0.01825"/>
      <mass value="0.17886"/>
    </inertial>
  </link>
  <!-- left ankle roll joint -->
  <joint name="l_ank_roll" type="revolute">
    <parent link="l_ank_pitch_link"/>
    <child link="l_ank_roll_link"/>
    <origin rpy="0.00000 0.00000 0.00000" xyz="0.00651 -0.01247 -0.03586"/>
    <axis xyz="1.00000 0.00000 0.00000"/>
    <limit effort="1000" lower="-2.827433388230814" upper="2.827433388230814" velocity="100"/>
    <dynamics damping="0.1" friction="0.0"/>
  </joint>
  <!-- left ankle roll link -->
  <link name="l_ank_roll_link">
    <visual>
      <origin rpy="0.00000 0.00000 0.00000" xyz="0.00130 0.00747 -0.02698"/>
      <geometry>
        <mesh filename="meshes/l_ank_roll.005.stl" scale="1.00000 1.00000 1.00000"/>
      </geometry>
      <material name="254,254,255.002">
        <color rgba="0.99216 0.99216 1.00000 1.00000"/>
      </material>
    </visual>
    <collision>
      <origin rpy="0.00000 0.00000 0.00000" xyz="0.00130 0.00747 -0.02698"/>
      <geometry>
        <mesh filename="meshes/l_ank_roll.005.stl" scale="1.00000 1.00000 1.00000"/>
      </geometry>
      <material name="254,254,255.002">
        <color rgba="0.99216 0.99216 1.00000 1.00000"/>
      </material>
    </collision>
    <inertial>
      <inertia ixx="0.00007" ixy="0.00000" ixz="0.00000" iyy="0.00014" iyz="0.00000" izz="0.00018"/>
      <origin rpy="0.00000 0.00000 0.00000" xyz="0.00130 0.00747 -0.02698"/>
      <mass value="0.06934"/>
    </inertial>
  </link>
  <joint name="l_sole_joint" type="fixed">
    <origin rpy="0.00000 0.00000 0.00000" xyz="-0.00000 0.00747 -0.03327"/>
    <parent link="l_ank_roll_link"/>
    <child link="l_sole"/>
  </joint>
  <link name="l_sole">
    <collision name="l_ank_roll_collision">
      <origin rpy="0.00000 0.00000 0.00000" xyz="-0.00330 0.00294 0.00309"/>
      <geometry>
        <box size="0.14500 0.09500 0.01200"/>
      </geometry>
    </collision>
    <inertial>
      <inertia ixx="0.00001" ixy="-0.00000" ixz="-0.00000" iyy="0.00002" iyz="-0.00000" izz="0.00003"/>
      <origin rpy="0.00000 0.00000 0.00000" xyz="-0.00064 0.00279 -0.00004"/>
      <mass value="0.01000"/>
    </inertial>
    <visual>
      <origin rpy="0.00000 0.00000 0.00000" xyz="0.00130 0.00000 0.00629"/>
      <material name="254,254,255.002">
        <color rgba="0.99216 0.99216 1.00000 1.00000"/>
      </material>
      <geometry>
        <mesh filename="meshes/l_ank_roll.stl" scale="1.00000 1.00000 1.00000"/>
      </geometry>
    </visual>
  </link>
  <!-- right hip yaw joint -->
  <joint name="r_hip_yaw" type="revolute">
    <parent link="body_link"/>
    <child link="r_hip_yaw_link"/>
    <origin rpy="0.00000 0.00000 0.00000" xyz="0.02401 -0.04596 0.03887"/>
    <axis xyz="0.00000 0.00000 -1.00000"/>
    <limit effort="1000" lower="-2.827433388230814" upper="2.827433388230814" velocity="100"/>
    <dynamics damping="0.1" friction="0.0"/>
  </joint>
  <!-- right hip yaw link -->
  <link name="r_hip_yaw_link">
    <visual>
      <origin rpy="0.00000 0.00000 0.00000" xyz="-0.02389 0.00050 -0.08787"/>
      <geometry>
        <mesh filename="meshes/r_hip_yaw.stl" scale="1.00000 1.00000 1.00000"/>
      </geometry>
      <material name="254,254,255.002">
        <color rgba="0.99216 0.99216 1.00000 1.00000"/>
      </material>
    </visual>
    <collision>
      <origin rpy="0.00000 0.00000 0.00000" xyz="-0.02389 0.00050 -0.08787"/>
      <geometry>
        <mesh filename="meshes/r_hip_yaw.stl" scale="1.00000 1.00000 1.00000"/>
      </geometry>
      <material name="254,254,255.002">
        <color rgba="0.99216 0.99216 1.00000 1.00000"/>
      </material>
    </collision>
    <inertial>
      <inertia ixx="3.0e-06" ixy="0" ixz="0" iyy="5.7e-06" iyz="0" izz="4.0e-06"/>
      <origin rpy="0.00000 0.00000 0.00000" xyz="0.00609 0.00022 -0.05911"/>
      <mass value="0.01181"/>
    </inertial>
  </link>
  <!-- right hip roll joint -->
  <joint name="r_hip_roll" type="revolute">
    <parent link="r_hip_yaw_link"/>
    <child link="r_hip_roll_link"/>
    <origin rpy="0.00000 0.00000 0.00000" xyz="-0.06059 0.00050 -0.07670"/>
    <axis xyz="-1.00000 0.00000 0.00000"/>
    <limit effort="1000" lower="-2.827433388230814" upper="2.827433388230814" velocity="100"/>
    <dynamics damping="0.1" friction="0.0"/>
  </joint>
  <!-- right hip roll link -->
  <link name="r_hip_roll_link">
    <visual>
      <origin rpy="0.00000 0.00000 0.00000" xyz="0.03670 0.00000 -0.01117"/>
      <geometry>
        <mesh filename="meshes/r_hip_roll.stl" scale="1.00000 1.00000 1.00000"/>
      </geometry>
      <material name="254,254,255.002">
        <color rgba="0.99216 0.99216 1.00000 1.00000"/>
      </material>
    </visual>
    <collision>
      <origin rpy="0.00000 0.00000 0.00000" xyz="0.03670 0.00000 -0.01117"/>
      <geometry>
        <mesh filename="meshes/r_hip_roll.stl" scale="1.00000 1.00000 1.00000"/>
      </geometry>
      <material name="254,254,255.002">
        <color rgba="0.99216 0.99216 1.00000 1.00000"/>
      </material>
    </collision>
    <inertial>
      <inertia ixx="0.00006" ixy="-0.00000" ixz="-0.00001" iyy="0.00016" iyz="-0.00000" izz="0.00014"/>
      <origin rpy="0.00000 0.00000 0.00000" xyz="0.03342 0.00003 -0.01483"/>
      <mass value="0.17886"/>
    </inertial>
  </link>
  <!-- right hip pitch joint -->
  <joint name="r_hip_pitch" type="revolute">
    <parent link="r_hip_roll_link"/>
    <child link="r_hip_pitch_link"/>
    <origin rpy="0.00000 0.00000 0.00000" xyz="0.05652 0.03126 0.00064"/>
    <axis xyz="0.00000 -1.00000 0.00000"/>
    <limit effort="1000" lower="-2.827433388230814" upper="2.827433388230814" velocity="100"/>
    <dynamics damping="0.1" friction="0.0"/>
  </joint>
  <!-- right hip pitch link -->
  <link name="r_hip_pitch_link">
    <visual>
      <origin rpy="0.00000 0.00000 0.00000" xyz="0.00047 -0.03141 -0.09145"/>
      <geometry>
        <mesh filename="meshes/r_hip_pitch.stl" scale="1.00000 1.00000 1.00000"/>
      </geometry>
      <material name="254,254,255.002">
        <color rgba="0.99216 0.99216 1.00000 1.00000"/>
      </material>
    </visual>
    <collision>
      <origin rpy="0.00000 0.00000 0.00000" xyz="0.00047 -0.03141 -0.09145"/>
      <geometry>
        <mesh filename="meshes/r_hip_pitch.stl" scale="1.00000 1.00000 1.00000"/>
      </geometry>
      <material name="254,254,255.002">
        <color rgba="0.99216 0.99216 1.00000 1.00000"/>
      </material>
    </collision>
    <inertial>
      <inertia ixx="0.00016" ixy="-0.00000" ixz="0.00000" iyy="0.00014" iyz="0.00001" izz="0.00004"/>
      <origin rpy="0.00000 0.00000 0.00000" xyz="0.00037 -0.03163 -0.07105"/>
      <mass value="0.11543"/>
    </inertial>
  </link>
  <!-- right knee joint -->
  <joint name="r_knee" type="revolute">
    <parent link="r_hip_pitch_link"/>
    <child link="r_knee_link"/>
    <origin rpy="0.00000 0.00000 0.00000" xyz="0.00089 0.00527 -0.11729"/>
    <axis xyz="0.00000 -1.00000 0.00000"/>
    <limit effort="1000" lower="-2.827433388230814" upper="2.827433388230814" velocity="100"/>
    <dynamics damping="0.1" friction="0.0"/>
  </joint>
  <!-- right knee link -->
  <link name="r_knee_link">
    <visual>
      <origin rpy="0.00000 0.00000 0.00000" xyz="0.00095 -0.03861 -0.05870"/>
      <geometry>
        <mesh filename="meshes/r_knee.stl" scale="1.00000 1.00000 1.00000"/>
      </geometry>
      <material name="254,254,255.002">
        <color rgba="0.99216 0.99216 1.00000 1.00000"/>
      </material>
    </visual>
    <collision>
      <origin rpy="0.00000 0.00000 0.00000" xyz="0.00095 -0.03861 -0.05870"/>
      <geometry>
        <mesh filename="meshes/r_knee.stl" scale="1.00000 1.00000 1.00000"/>
      </geometry>
      <material name="254,254,255.002">
        <color rgba="0.99216 0.99216 1.00000 1.00000"/>
      </material>
    </collision>
    <inertial>
      <inertia ixx="0.00006" ixy="-0.00000" ixz="0.00000" iyy="0.00004" iyz="0.00000" izz="0.00002"/>
      <origin rpy="0.00000 0.00000 0.00000" xyz="0.00112 -0.03905 -0.05871"/>
      <mass value="0.04015"/>
    </inertial>
  </link>
  <!-- right ankle pitch joint -->
  <joint name="r_ank_pitch" type="revolute">
    <parent link="r_knee_link"/>
    <child link="r_ank_pitch_link"/>
    <origin rpy="0.00000 0.00000 0.00000" xyz="0.00062 -0.05112 -0.11684"/>
    <axis xyz="0.00000 1.00000 0.00000"/>
    <limit effort="1000" lower="-2.827433388230814" upper="2.827433388230814" velocity="100"/>
    <dynamics damping="0.1" friction="0.0"/>
  </joint>
  <!-- right ankle pitch link -->
  <link name="r_ank_pitch_link">
    <visual>
      <origin rpy="0.00000 0.00000 0.00000" xyz="-0.02296 0.01471 -0.01828"/>
      <geometry>
        <mesh filename="meshes/r_ank_pitch.stl" scale="1.00000 1.00000 1.00000"/>
      </geometry>
      <material name="254,254,255.002">
        <color rgba="0.99216 0.99216 1.00000 1.00000"/>
      </material>
    </visual>
    <collision>
      <origin rpy="0.00000 0.00000 0.00000" xyz="-0.02296 0.01471 -0.01828"/>
      <geometry>
        <mesh filename="meshes/r_ank_pitch.stl" scale="1.00000 1.00000 1.00000"/>
      </geometry>
      <material name="254,254,255.002">
        <color rgba="0.99216 0.99216 1.00000 1.00000"/>
      </material>
    </collision>
    <inertial>
      <inertia ixx="0.00006" ixy="-0.00000" ixz="0.00000" iyy="0.00016" iyz="-0.00000" izz="0.00014"/>
      <origin rpy="0.00000 0.00000 0.00000" xyz="-0.02296 0.01471 -0.01828"/>
      <mass value="0.17886"/>
    </inertial>
  </link>
  <!-- right ankle roll joint -->
  <joint name="r_ank_roll" type="revolute">
    <parent link="r_ank_pitch_link"/>
    <child link="r_ank_roll_link"/>
    <origin rpy="0.00000 0.00000 0.00000" xyz="0.00651 0.01433 -0.03586"/>
    <axis xyz="1.00000 0.00000 0.00000"/>
    <limit effort="1000" lower="-2.827433388230814" upper="2.827433388230814" velocity="100"/>
    <dynamics damping="0.1" friction="0.0"/>
  </joint>
  <!-- right ankle roll link -->
  <link name="r_ank_roll_link">
    <visual>
      <origin rpy="0.00000 0.00000 0.00000" xyz="-0.00000 -0.00773 -0.02925"/>
      <geometry>
        <mesh filename="meshes/r_ank_roll.005.stl" scale="1.00000 1.00000 1.00000"/>
      </geometry>
      <material name="254,254,255.002">
        <color rgba="0.99216 0.99216 1.00000 1.00000"/>
      </material>
    </visual>
    <collision>
      <origin rpy="0.00000 0.00000 0.00000" xyz="-0.00000 -0.00773 -0.02925"/>
      <geometry>
        <mesh filename="meshes/r_ank_roll.005.stl" scale="1.00000 1.00000 1.00000"/>
      </geometry>
      <material name="254,254,255.002">
        <color rgba="0.99216 0.99216 1.00000 1.00000"/>
      </material>
    </collision>
    <inertial>
      <inertia ixx="0.00007" ixy="0.00000" ixz="0.00000" iyy="0.00014" iyz="0.00000" izz="0.00018"/>
      <origin rpy="0.00000 0.00000 0.00000" xyz="-0.00000 -0.00773 -0.02925"/>
      <mass value="0.06934"/>
    </inertial>
  </link>
  <joint name="r_sole_joint" type="fixed">
    <origin rpy="0.00000 0.00000 0.00000" xyz="-0.00000 -0.00773 -0.03327"/>
    <parent link="r_ank_roll_link"/>
    <child link="r_sole"/>
  </joint>
  <link name="r_sole">
    <collision name="r_ank_roll_collision">
      <origin rpy="0.00000 0.00000 0.00000" xyz="-0.00330 -0.00255 0.00309"/>
      <geometry>
        <box size="0.14500 0.09500 0.01200"/>
      </geometry>
    </collision>
    <inertial>
      <inertia ixx="0.00001" ixy="0.00000" ixz="-0.00000" iyy="0.00002" iyz="0.00000" izz="0.00003"/>
      <origin rpy="0.00000 0.00000 0.00000" xyz="-0.00094 -0.00227 -0.00008"/>
      <mass value="0.01000"/>
    </inertial>
    <visual>
      <origin rpy="0.00000 0.00000 0.00000" xyz="0.00000 -0.00000 0.00402"/>
      <material name="254,254,255.002">
        <color rgba="0.99216 0.99216 1.00000 1.00000"/>
      </material>
      <geometry>
        <mesh filename="meshes/r_ank_roll.005.stl" scale="1.00000 1.00000 1.00000"/>
      </geometry>
    </visual>
  </link>
  <!-- left shoulder pitch joint -->
  <joint name="l_sho_pitch" type="revolute">
    <parent link="body_link"/>
    <child link="l_sho_pitch_link"/>
    <origin rpy="0.00000 0.00000 0.00000" xyz="-0.00676 0.06539 0.18530"/>
    <axis xyz="0.00000 1.00000 0.00000"/>
    <limit effort="1000" lower="-2.827433388230814" upper="2.827433388230814" velocity="100"/>
    <dynamics damping="0.1" friction="0.0"/>
  </joint>
  <!-- left shoulder pitch link -->
  <link name="l_sho_pitch_link">
    <visual>
      <origin rpy="0.00000 0.00000 0.00000" xyz="-0.00064 0.02750 -0.00646"/>
      <geometry>
        <mesh filename="meshes/l_sho_pitch.stl" scale="1.00000 1.00000 1.00000"/>
      </geometry>
      <material name="254,254,255.002">
        <color rgba="0.99216 0.99216 1.00000 1.00000"/>
      </material>
    </visual>
    <collision>
      <origin rpy="0.00000 0.00000 0.00000" xyz="-0.00064 0.02750 -0.00646"/>
      <geometry>
        <mesh filename="meshes/l_sho_pitch.stl" scale="1.00000 1.00000 1.00000"/>
      </geometry>
      <material name="254,254,255.002">
        <color rgba="0.99216 0.99216 1.00000 1.00000"/>
      </material>
    </collision>
    <inertial>
      <inertia ixx="5.4e-06" ixy="0" ixz="0" iyy="4.7e-06" iyz="0" izz="5.1e-06"/>
      <origin rpy="0.00000 0.00000 0.00000" xyz="-0.00072 0.02775 -0.00669"/>
      <mass value="0.01176"/>
    </inertial>
  </link>
  <!-- left shoulder roll joint -->
  <joint name="l_sho_roll" type="revolute">
    <parent link="l_sho_pitch_link"/>
    <child link="l_sho_roll_link"/>
    <origin rpy="0.00000 0.00000 0.00000" xyz="-0.00378 0.04958 -0.02794"/>
    <axis xyz="-1.00000 0.00000 0.00000"/>
    <limit effort="1000" lower="-2.827433388230814" upper="2.827433388230814" velocity="100"/>
    <dynamics damping="0.1" friction="0.0"/>
  </joint>
  <!-- left shoulder roll link -->
  <link name="l_sho_roll_link">
    <visual>
      <origin rpy="0.00000 0.00000 0.00000" xyz="0.00000 -0.00000 -0.05204"/>
      <geometry>
        <mesh filename="meshes/l_sho_roll.stl" scale="1.00000 1.00000 1.00013"/>
      </geometry>
      <material name="254,254,255.002">
        <color rgba="0.99216 0.99216 1.00000 1.00000"/>
      </material>
    </visual>
    <collision>
      <origin rpy="0.00000 0.00000 0.00000" xyz="0.00000 -0.00000 -0.05204"/>
      <geometry>
        <mesh filename="meshes/l_sho_roll.stl" scale="1.00000 1.00000 1.00013"/>
      </geometry>
      <material name="254,254,255.002">
        <color rgba="0.99216 0.99216 1.00000 1.00000"/>
      </material>
    </collision>
    <inertial>
      <inertia ixx="0.00021" ixy="0.00000" ixz="-0.00002" iyy="0.00022" iyz="0.00000" izz="0.00004"/>
      <origin rpy="0.00000 0.00000 0.00000" xyz="0.00000 -0.00000 -0.05204"/>
      <mass value="0.17758"/>
    </inertial>
  </link>
  <!-- left elbow joint -->
  <joint name="l_el" type="revolute">
    <parent link="l_sho_roll_link"/>
    <child link="l_el_link"/>
    <origin rpy="0.00000 0.00000 0.00000" xyz="-0.01599 0.01357 -0.09291"/>
    <axis xyz="0.00000 1.00000 0.00000"/>
    <limit effort="1000" lower="-2.827433388230814" upper="2.827433388230814" velocity="100"/>
    <dynamics damping="0.1" friction="0.0"/>
  </joint>
  <!-- left elbow link -->
  <link name="l_el_link">
    <visual>
      <origin rpy="0.00000 0.00000 0.00000" xyz="0.01579 0.00000 -0.07402"/>
      <geometry>
        <mesh filename="meshes/l_el.stl" scale="1.00000 1.00000 1.00000"/>
      </geometry>
      <material name="254,254,255.002">
        <color rgba="0.99216 0.99216 1.00000 1.00000"/>
      </material>
    </visual>
    <collision>
      <origin rpy="0.00000 0.00000 0.00000" xyz="0.01579 0.00000 -0.07402"/>
      <geometry>
        <mesh filename="meshes/l_el.stl" scale="1.00000 1.00000 1.00000"/>
      </geometry>
      <material name="254,254,255.002">
        <color rgba="0.99216 0.99216 1.00000 1.00000"/>
      </material>
    </collision>
    <inertial>
      <inertia ixx="0.00011" ixy="0" ixz="0" iyy="0.00011" iyz="0" izz="0.00002"/>
      <origin rpy="0.00000 0.00000 0.00000" xyz="0.01530 -0.00132 -0.06628"/>
      <mass value="0.04127"/>
    </inertial>
  </link>
  <!-- right shoulder pitch joint -->
  <joint name="r_sho_pitch" type="revolute">
    <parent link="body_link"/>
    <child link="r_sho_pitch_link"/>
    <origin rpy="0.00000 0.00000 0.00000" xyz="-0.00676 -0.07353 0.18530"/>
    <axis xyz="0.00000 -1.00000 0.00000"/>
    <limit effort="1000" lower="-2.827433388230814" upper="2.827433388230814" velocity="100"/>
    <dynamics damping="0.1" friction="0.0"/>
  </joint>
  <!-- right shoulder pitch link -->
  <link name="r_sho_pitch_link">
    <visual>
      <origin rpy="0.00000 0.00000 0.00000" xyz="-0.00122 -0.02254 -0.01077"/>
      <geometry>
        <mesh filename="meshes/r_sho_pitch.stl" scale="1.00000 1.00000 1.00000"/>
      </geometry>
      <material name="254,254,255.002">
        <color rgba="0.99216 0.99216 1.00000 1.00000"/>
      </material>
    </visual>
    <collision>
      <origin rpy="0.00000 0.00000 0.00000" xyz="-0.00122 -0.02254 -0.01077"/>
      <geometry>
        <mesh filename="meshes/r_sho_pitch.stl" scale="1.00000 1.00000 1.00000"/>
      </geometry>
      <material name="254,254,255.002">
        <color rgba="0.99216 0.99216 1.00000 1.00000"/>
      </material>
    </collision>
    <inertial>
      <inertia ixx="5.4e-06" ixy="0" ixz="0" iyy="4.7e-06" iyz="0" izz="5.1e-06"/>
      <origin rpy="0.00000 0.00000 0.00000" xyz="-0.00120 -0.02209 -0.00678"/>
      <mass value="0.01176"/>
    </inertial>
  </link>
  <!-- right shoulder roll joint -->
  <joint name="r_sho_roll" type="revolute">
    <parent link="r_sho_pitch_link"/>
    <child link="r_sho_roll_link"/>
    <origin rpy="0.00000 0.00000 0.00000" xyz="-0.00442 -0.04381 -0.02762"/>
    <axis xyz="1.00000 0.00000 0.00000"/>
    <limit effort="1000" lower="-2.827433388230814" upper="2.827433388230814" velocity="100"/>
    <dynamics damping="0.1" friction="0.0"/>
  </joint>
  <!-- right shoulder roll link -->
  <link name="r_sho_roll_link">
    <visual>
      <origin rpy="0.00000 0.00000 0.00000" xyz="-0.00000 0.00000 -0.05244"/>
      <geometry>
        <mesh filename="meshes/r_sho_roll.stl" scale="1.00000 1.00000 1.00000"/>
      </geometry>
      <material name="254,254,255.002">
        <color rgba="0.99216 0.99216 1.00000 1.00000"/>
      </material>
    </visual>
    <collision>
      <origin rpy="0.00000 0.00000 0.00000" xyz="-0.00000 0.00000 -0.05244"/>
      <geometry>
        <mesh filename="meshes/r_sho_roll.stl" scale="1.00000 1.00000 1.00000"/>
      </geometry>
      <material name="254,254,255.002">
        <color rgba="0.99216 0.99216 1.00000 1.00000"/>
      </material>
    </collision>
    <inertial>
      <inertia ixx="0.00021" ixy="-0.00000" ixz="-0.00002" iyy="0.00022" iyz="-0.00000" izz="0.00004"/>
      <origin rpy="0.00000 0.00000 0.00000" xyz="-0.00000 0.00000 -0.05244"/>
      <mass value="0.17758"/>
    </inertial>
  </link>
  <!-- right elbow joint -->
  <joint name="r_el" type="revolute">
    <parent link="r_sho_roll_link"/>
    <child link="r_el_link"/>
    <origin rpy="0.00000 0.00000 0.00000" xyz="-0.01605 -0.01348 -0.09326"/>
    <axis xyz="0.00000 -1.00000 0.00000"/>
    <limit effort="1000" lower="-2.827433388230814" upper="2.827433388230814" velocity="100"/>
    <dynamics damping="0.1" friction="0.0"/>
  </joint>
  <!-- right elbow link -->
  <link name="r_el_link">
    <visual>
      <origin rpy="0.00000 0.00000 0.00000" xyz="0.01577 0.00000 -0.07409"/>
      <geometry>
        <mesh filename="meshes/r_el.stl" scale="1.00000 1.00000 1.00000"/>
      </geometry>
      <material name="254,254,255.002">
        <color rgba="0.99216 0.99216 1.00000 1.00000"/>
      </material>
    </visual>
    <collision>
      <origin rpy="0.00000 0.00000 0.00000" xyz="0.01577 0.00000 -0.07409"/>
      <geometry>
        <mesh filename="meshes/r_el.stl" scale="1.00000 1.00000 1.00000"/>
      </geometry>
      <material name="254,254,255.002">
        <color rgba="0.99216 0.99216 1.00000 1.00000"/>
      </material>
    </collision>
    <inertial>
      <inertia ixx="0.00011" ixy="0" ixz="0" iyy="0.00011" iyz="0" izz="1.6e-05"/>
      <origin rpy="0.00000 0.00000 0.00000" xyz="0.01529 0.00132 -0.06635"/>
      <mass value="0.04127"/>
    </inertial>
  </link>
  <!-- head pan joint -->
  <joint name="head_pan" type="revolute">
    <parent link="body_link"/>
    <child link="head_pan_link"/>
    <origin rpy="0.00000 0.00000 0.00000" xyz="0.01902 -0.00134 0.18511"/>
    <axis xyz="0 0 1"/>
    <limit effort="1000" lower="-2.827433388230814" upper="2.827433388230814" velocity="100"/>
    <dynamics damping="0.1" friction="0.0"/>
  </joint>
  <!-- head pan link -->
  <link name="head_pan_link">
    <visual>
      <origin rpy="0.00000 0.00000 0.00000" xyz="0.00703 -0.00031 0.04142"/>
      <geometry>
        <mesh filename="meshes/neck.stl" scale="1.00000 1.00000 1.00000"/>
      </geometry>
      <material name="254,254,255.002">
        <color rgba="0.99216 0.99216 1.00000 1.00000"/>
      </material>
    </visual>
    <collision>
      <origin rpy="0.00000 0.00000 0.00000" xyz="0.00703 -0.00031 0.04142"/>
      <geometry>
        <mesh filename="meshes/neck.stl" scale="1.00000 1.00000 1.00000"/>
      </geometry>
      <material name="254,254,255.002">
        <color rgba="0.99216 0.99216 1.00000 1.00000"/>
      </material>
    </collision>
    <inertial>
      <inertia ixx="3.7494437e-06" ixy="0" ixz="0" iyy="4.291624e-06" iyz="0" izz="4.5314214e-06"/>
      <origin rpy="0.00000 0.00000 0.00000" xyz="0.00703 -0.00031 0.04142"/>
      <mass value="0.01176"/>
    </inertial>
  </link>
  <!-- head tilt joint -->
  <joint name="head_tilt" type="revolute">
    <parent link="head_pan_link"/>
    <child link="head_tilt_link"/>
    <origin rpy="0.00000 0.00000 0.00000" xyz="0.01877 -0.00004 0.04264"/>
    <axis xyz="0 -1 0"/>
    <limit effort="1000" lower="-2.827433388230814" upper="2.827433388230814" velocity="100"/>
    <dynamics damping="0.1" friction="0.0"/>
  </joint>
  <!-- head tilt link -->
  <link name="head_tilt_link">
    <visual>
      <origin rpy="0.00000 0.00000 0.00000" xyz="0.00326 0.00000 0.04010"/>
      <geometry>
        <mesh filename="meshes/camera.stl" scale="1.00000 1.00000 1.00000"/>
      </geometry>
      <material name="254,254,255.002">
        <color rgba="0.99216 0.99216 1.00000 1.00000"/>
      </material>
    </visual>
    <collision>
      <origin rpy="0.00000 0.00000 0.00000" xyz="0.00326 0.00000 0.04010"/>
      <geometry>
        <mesh filename="meshes/camera.stl" scale="1.00000 1.00000 1.00000"/>
      </geometry>
      <material name="254,254,255.002">
        <color rgba="0.99216 0.99216 1.00000 1.00000"/>
      </material>
    </collision>
    <inertial>
      <inertia ixx="0.00008" ixy="-0.00000" ixz="-0.00002" iyy="0.00009" iyz="-0.00000" izz="0.00008"/>
      <origin rpy="0.00000 0.00000 0.00000" xyz="0.00375 -0.00000 0.04044"/>
      <mass value="0.13631"/>
    </inertial>
  </link>
  <!-- camera joint -->
  <joint name="camera_joint" type="fixed">
    <parent link="head_tilt_link"/>
    <child link="cam_link"/>
    <origin rpy="-0.00000 1.57080 0.00000" xyz="0.00326 0.00000 0.04677"/>
  </joint>
  <!-- camera link -->
  <link name="cam_link">
    </link>
</robot>
